<?xml version="1.0"?>
<robot xmlns:xacro="http://www.ros.org/wiki/xacro">

    <xacro:include filename="inertial_macros.xacro"/>

    <!-- base link -->
    <link name="base_link">
    </link>

    <joint name="base_link" type="fixed">
        <parent link="base_link"/>
        <child link="chassis"/>
        <origin xyz="-0.1 0 0"/>    
    </joint>

    <!-- chassis link -->
    <link name="chassis">
        <visual>
            <origin xyz="0.25 0 0.075"/>
            <geometry>
                <box size="0.4 0.3 0.15"/>
            </geometry>
        </visual>
        <collision>
            <origin xyz="0.15 0 0.075"/>
            <geometry>
                <box size="0.3 0.3 0.15"/>
            </geometry>
        </collision>
        <xacro:inertial_box mass="0.8" x="0.3" y="0.3" z="0.15">
            <origin xyz="0.15 0 0.075" rpy="0 0 0"/>
        </xacro:inertial_box>
    </link>

    <!-- left wheel joint -->
    <joint name="left_wheel_joint" type="continuous">
        <parent link="base_link"/>
        <child link="left_wheel"/>
        <origin xyz="0 0.175 0" rpy="-${pi/2} 0 0"/>
        <axis xyz="0 0 1"/>   
    </joint>

    <!-- left wheel link -->
    <link name="left_wheel">
        <visual>
            <geometry>
                <cylinder radius="0.05" length="0.04"/>
            </geometry>
        </visual>
	      <collision>
	          <geometry>
	              <sphere radius="0.05"/>
	          </geometry>
	      </collision>
        <xacro:inertial_cylinder mass="0.1" length="0.04" radius="0.05">
            <origin xyz="0 0 0" rpy="0 0 0"/>
        </xacro:inertial_cylinder> 
    </link>

    <!-- right wheel joint -->
    <joint name="right_wheel_joint" type="continuous">
        <parent link="base_link"/>
        <child link="right_wheel"/>
        <origin xyz="0 -0.175 0" rpy="${pi/2} 0 0"/>
        <axis xyz="0 0 -1"/>    
    </joint>

    <!-- right wheel link -->
    <link name="right_wheel">
        <visual>
            <geometry>
                <cylinder radius="0.05" length="0.04"/>
            </geometry>
        </visual>
	      <collision>
	          <geometry>
	              <sphere radius="0.05"/>
	          </geometry>
	      </collision>
        <xacro:inertial_cylinder mass="0.1" length="0.04" radius="0.05">
            <origin xyz="0 0 0" rpy="0 0 0"/>
        </xacro:inertial_cylinder>
    </link>

    <!-- caster wheel joint -->
    <joint name="caster_wheel_joint" type="fixed">
        <parent link="chassis"/>
        <child link="caster_wheel"/>
        <origin xyz="0.4 0 0"/>  
    </joint>

    <!-- caster wheel link -->
    <link name="caster_wheel">
        <collision>
            <geometry>
                <sphere radius="0.05"/>
            </geometry>
        </collision>
        <visual>
            <geometry>
                <sphere radius="0.05"/>
            </geometry>
        </visual>
        <xacro:inertial_sphere mass="0.1" radius="0.05">
            <origin xyz="0 0 0" rpy="0 0 0"/>
        </xacro:inertial_sphere>

    </link>



    <!-- laser_frame -->
    <link name="camera_link">
        <visual>
            <geometry>
                <box size="0.02 0.1 0.1"/>
            </geometry>¿
        </visual>
        <xacro:inertial_box mass="0.01" x="0.02" y="0.1" z="0.1">
            <origin xyz="0 0 0" rpy="0 0 0"/>
        </xacro:inertial_box>
    </link>

    <joint name="camera_joint" type="fixed">
        <parent link="chassis"/>
        <child link="camera_link"/>
        <origin xyz="0.4 0 0.175" rpy="0 0 0"/> 
    </joint>


    <!-- laser_frame -->
    <link name="imu_link">
        <visual>
            <geometry>
                <box size="0.02 0.02 0.04"/>
            </geometry>
        </visual>
        <xacro:inertial_box mass="0.02" x="0.2" y="0.02" z="0.04">
            <origin xyz="0 0 0" rpy="0 0 0"/>
        </xacro:inertial_box>
    </link>

    <joint name="imu_joint" type="fixed">
        <parent link="chassis"/>
        <child link="imu_link"/>
        <origin xyz="0.3 0 0.175" rpy="0 0 0"/> 
    </joint>


</robot>